ERROR:ex:Error!
Traceback (most recent call last):
  File "D:\PyCharm_projects\SubVPbot\test\logs\test_logging.py", line 8, in <module>
    raise RuntimeError
RuntimeError
